Process SpawnProcess-2:
Traceback (most recent call last):
  File "/nix/store/vnvdzw4182wb2ifzi0cczhv80yfnpx1q-python3-3.12.11/lib/python3.12/multiprocessing/process.py", line 314, in _bootstrap
    self.run()
  File "/nix/store/vnvdzw4182wb2ifzi0cczhv80yfnpx1q-python3-3.12.11/lib/python3.12/multiprocessing/process.py", line 108, in run
    self._target(*self._args, **self._kwargs)
  File "/home/runner/workspace/.pythonlibs/lib/python3.12/site-packages/uvicorn/_subprocess.py", line 80, in subprocess_started
    target(sockets=sockets)
  File "/home/runner/workspace/.pythonlibs/lib/python3.12/site-packages/uvicorn/server.py", line 67, in run
    return asyncio_run(self.serve(sockets=sockets), loop_factory=self.config.get_loop_factory())
           ^^^^^^^^^^^^^^^^^^^^^^^^^^^^^^^^^^^^^^^^^^^^^^^^^^^^^^^^^^^^^^^^^^^^^^^^^^^^^^^^^^^^^
  File "/nix/store/vnvdzw4182wb2ifzi0cczhv80yfnpx1q-python3-3.12.11/lib/python3.12/asyncio/runners.py", line 195, in run
    return runner.run(main)
           ^^^^^^^^^^^^^^^^
  File "/nix/store/vnvdzw4182wb2ifzi0cczhv80yfnpx1q-python3-3.12.11/lib/python3.12/asyncio/runners.py", line 118, in run
    return self._loop.run_until_complete(task)
           ^^^^^^^^^^^^^^^^^^^^^^^^^^^^^^^^^^^
  File "/nix/store/vnvdzw4182wb2ifzi0cczhv80yfnpx1q-python3-3.12.11/lib/python3.12/asyncio/base_events.py", line 691, in run_until_complete
    return future.result()
           ^^^^^^^^^^^^^^^
  File "/home/runner/workspace/.pythonlibs/lib/python3.12/site-packages/uvicorn/server.py", line 71, in serve
    await self._serve(sockets)
  File "/home/runner/workspace/.pythonlibs/lib/python3.12/site-packages/uvicorn/server.py", line 78, in _serve
    config.load()
  File "/home/runner/workspace/.pythonlibs/lib/python3.12/site-packages/uvicorn/config.py", line 438, in load
    self.loaded_app = import_from_string(self.app)
                      ^^^^^^^^^^^^^^^^^^^^^^^^^^^^
  File "/home/runner/workspace/.pythonlibs/lib/python3.12/site-packages/uvicorn/importer.py", line 22, in import_from_string
    raise exc from None
  File "/home/runner/workspace/.pythonlibs/lib/python3.12/site-packages/uvicorn/importer.py", line 19, in import_from_string
    module = importlib.import_module(module_str)
             ^^^^^^^^^^^^^^^^^^^^^^^^^^^^^^^^^^^
  File "/nix/store/vnvdzw4182wb2ifzi0cczhv80yfnpx1q-python3-3.12.11/lib/python3.12/importlib/__init__.py", line 90, in import_module
    return _bootstrap._gcd_import(name[level:], package, level)
           ^^^^^^^^^^^^^^^^^^^^^^^^^^^^^^^^^^^^^^^^^^^^^^^^^^^^
  File "<frozen importlib._bootstrap>", line 1387, in _gcd_import
  File "<frozen importlib._bootstrap>", line 1360, in _find_and_load
  File "<frozen importlib._bootstrap>", line 1331, in _find_and_load_unlocked
  File "<frozen importlib._bootstrap>", line 935, in _load_unlocked
  File "<frozen importlib._bootstrap_external>", line 999, in exec_module
  File "<frozen importlib._bootstrap>", line 488, in _call_with_frames_removed
  File "/home/runner/workspace/main.py", line 22, in <module>
    from routers.seasons import router as seasons_router
  File "/home/runner/workspace/routers/seasons.py", line 8, in <module>
    from utils.exceptions import ResourceNotFoundException
ModuleNotFoundError: No module named 'utils.exceptions'; 'utils' is not a package
